Traceback (most recent call last):
  File "/home/pat/anaconda3/lib/python3.9/site-packages/jupyter_cache/executors/utils.py", line 58, in single_nb_execution
    executenb(
  File "/home/pat/anaconda3/lib/python3.9/site-packages/nbclient/client.py", line 1112, in execute
    return NotebookClient(nb=nb, resources=resources, km=km, **kwargs).execute()
  File "/home/pat/anaconda3/lib/python3.9/site-packages/nbclient/util.py", line 74, in wrapped
    return just_run(coro(*args, **kwargs))
  File "/home/pat/anaconda3/lib/python3.9/site-packages/nbclient/util.py", line 53, in just_run
    return loop.run_until_complete(coro)
  File "/home/pat/anaconda3/lib/python3.9/asyncio/base_events.py", line 642, in run_until_complete
    return future.result()
  File "/home/pat/anaconda3/lib/python3.9/site-packages/nbclient/client.py", line 553, in async_execute
    await self.async_execute_cell(
  File "/home/pat/anaconda3/lib/python3.9/site-packages/nbclient/client.py", line 857, in async_execute_cell
    self._check_raise_for_error(cell, exec_reply)
  File "/home/pat/anaconda3/lib/python3.9/site-packages/nbclient/client.py", line 760, in _check_raise_for_error
    raise CellExecutionError.from_cell_and_msg(cell, exec_reply_content)
nbclient.exceptions.CellExecutionError: An error occurred while executing the following cell:
------------------
parent,folder,subfolder=parent_folder_subfolder()
------------------

[0;31m---------------------------------------------------------------------------[0m
[0;31mIndexError[0m                                Traceback (most recent call last)
[0;32m/tmp/ipykernel_16066/3824672720.py[0m in [0;36m<module>[0;34m[0m
[0;32m----> 1[0;31m [0mparent[0m[0;34m,[0m[0mfolder[0m[0;34m,[0m[0msubfolder[0m[0;34m=[0m[0mparent_folder_subfolder[0m[0;34m([0m[0;34m)[0m[0;34m[0m[0;34m[0m[0m
[0m
[0;32m<string>[0m in [0;36mparent_folder_subfolder[0;34m(default)[0m

[0;32m~/anaconda3/lib/python3.9/site-packages/ipynbname/__init__.py[0m in [0;36mname[0;34m()[0m
[1;32m     91[0m         [0;32mor[0m [0mraises[0m [0ma[0m [0mFileNotFoundError[0m [0mexception[0m [0;32mif[0m [0mit[0m [0mcannot[0m [0mbe[0m [0mdetermined[0m[0;34m.[0m[0;34m[0m[0;34m[0m[0m
[1;32m     92[0m     """
[0;32m---> 93[0;31m     [0m_[0m[0;34m,[0m [0mpath[0m [0;34m=[0m [0m_find_nb_path[0m[0;34m([0m[0;34m)[0m[0;34m[0m[0;34m[0m[0m
[0m[1;32m     94[0m     [0;32mif[0m [0mpath[0m[0;34m:[0m[0;34m[0m[0;34m[0m[0m
[1;32m     95[0m         [0;32mreturn[0m [0mpath[0m[0;34m.[0m[0mstem[0m[0;34m[0m[0;34m[0m[0m

[0;32m~/anaconda3/lib/python3.9/site-packages/ipynbname/__init__.py[0m in [0;36m_find_nb_path[0;34m()[0m
[1;32m     73[0m [0;32mdef[0m [0m_find_nb_path[0m[0;34m([0m[0;34m)[0m [0;34m->[0m [0mUnion[0m[0;34m[[0m[0mTuple[0m[0;34m[[0m[0mdict[0m[0;34m,[0m [0mPurePath[0m[0;34m][0m[0;34m,[0m [0mTuple[0m[0;34m[[0m[0;32mNone[0m[0;34m,[0m [0;32mNone[0m[0;34m][0m[0;34m][0m[0;34m:[0m[0;34m[0m[0;34m[0m[0m
[1;32m     74[0m     [0;32mtry[0m[0;34m:[0m[0;34m[0m[0;34m[0m[0m
[0;32m---> 75[0;31m         [0mkernel_id[0m [0;34m=[0m [0m_get_kernel_id[0m[0;34m([0m[0;34m)[0m[0;34m[0m[0;34m[0m[0m
[0m[1;32m     76[0m     [0;32mexcept[0m [0;34m([0m[0mMultipleInstanceError[0m[0;34m,[0m [0mRuntimeError[0m[0;34m)[0m[0;34m:[0m[0;34m[0m[0;34m[0m[0m
[1;32m     77[0m         [0;32mreturn[0m [0;32mNone[0m[0;34m,[0m [0;32mNone[0m  [0;31m# Could not determine[0m[0;34m[0m[0;34m[0m[0m

[0;32m~/anaconda3/lib/python3.9/site-packages/ipynbname/__init__.py[0m in [0;36m_get_kernel_id[0;34m()[0m
[1;32m     46[0m     """
[1;32m     47[0m     [0mconnection_file[0m [0;34m=[0m [0mPath[0m[0;34m([0m[0mipykernel[0m[0;34m.[0m[0mget_connection_file[0m[0;34m([0m[0;34m)[0m[0;34m)[0m[0;34m.[0m[0mstem[0m[0;34m[0m[0;34m[0m[0m
[0;32m---> 48[0;31m     [0mkernel_id[0m [0;34m=[0m [0mconnection_file[0m[0;34m.[0m[0msplit[0m[0;34m([0m[0;34m'-'[0m[0;34m,[0m [0;36m1[0m[0;34m)[0m[0;34m[[0m[0;36m1[0m[0;34m][0m[0;34m[0m[0;34m[0m[0m
[0m[1;32m     49[0m     [0;32mreturn[0m [0mkernel_id[0m[0;34m[0m[0;34m[0m[0m
[1;32m     50[0m [0;34m[0m[0m

[0;31mIndexError[0m: list index out of range
IndexError: list index out of range

